Workbook

Sheet MiniGrid
A1: Indicators | B1: Current Quarter | C1: To-date
A2: Minimum Subsidy Tender for Mini Grids
A3: Isolated Mini Grid
A4: Benefiting Communities | B4: 34 | D4: Benefiting Communities
A5: Isolated Mini Grid Approved | D5: Isolated Mini Grid Approved
A6: Isolated Mini Grid Commissioned | D6: Isolated Mini Grid Commissioned
A7: Isolated Mini-Grid Ongoing | D7: Isolated Mini-Grid Ongoing
A8: Population of Beneficiaries | D8: Population of Beneficiaries
A9: Population of Female Beneficiaries | D9: Population of Female Beneficiaries
A10: Population of Household Beneficiary | D10: Population of Household Beneficiary
A11: Population of Female Headed Household Beneficiaries | D11: Population of Female Headed Household Beneficiaries
A12: Population of MSME Beneficiaries | D12: Population of MSME Beneficiaries
A13: Population of Female Managed MSME Beneficiaries | D13: Population of Female Managed MSME Beneficiaries
A14: Population of New MSMEs enabled | D14: Population of New MSMEs enabled
A15: Population of Public Institution Beneficiaries | D15: Population of Public Institutition Beneficiaries
A16: Mini-Grid installed energy capacity | D16: Mini-Grid installed energy capacity
... A19: Average outage events per month | D19: Average outage events per month
A20: Grant Disbursed
A21: Private Sector Fund Mobilised
A22: Gasoline generator sets replaced | B22: 344
A24: Interconnected Mini Grid | D24: Gasoline generator sets replaced
A25: Benefiting Communities | B25: 35
A26: Interconnected Mini Grid Approved
A27: Isolated Mini Grid Commissioned
A28: Interconnected Mini-Grid Ongoing
A29: Population of Households connected
A30: Population of Female Households connected
A31: Population of PUE and Economic Users connected
A32: Population of Female Headed Household beneficiaries
A33: Population of MSME beneficiaries
A34: Population of Female Managed MSME beneficiaries
A35: Population of New MSMEs enabled
A36: Population of Public Institution beneficiary
A37: Mini-Grid installed energy capacity
... A42: Private Sector Fund Mobilised
A43: Gasoline generator sets replaced | B43: 36
A45: Solar Rooftop Solutions
A46: Solar Rooftop Solutions Approved | B46: 37
A47: Solar Rooftop Solutions Commissioned
A48: Population of Benefiting Health Institutions
...

Sheet StandAlone
B1: STAND-ALONE SOLAR SYSTEMS
B3: Reporting Period______________________________________
B4: Indicators | C4: Current Quarter | D4: To-date
B5: Performance Based Grants for Standalone Solar Systems
B6: Solar Home Systems deployed | C6: 23
B7: Installed Energy Capacity
B8: Benefitting Households
B9: Benefiting Female Headed Households
B10: Benefiting MSMES
B11: Benefiting Female Owned MSMES
B12: Benefiting Agricultural Business
B13: Benefiting Female Owned Agricultural Business
B14: Gasoline generator sets replaced | C14: 24
B16: Catalytic Grants
B17: Poor/Displaced Communities Identified | C17: 25
B18: Poor/Displaced Communities Approved
B19: Solar Solution Approved
B20: Solar Solution Completed
B21: Solar Solution On-going
B22: Installed Energy Capacity
B23: Population of Households
B24: Population of Female Headed Households
B25: Population of PUE and Economic Users
B26: Population of Female PUE and Economic Users
B27: Gasoline generator sets replaced | C27: 26
B29: Summary and Next Steps
B30: Key Achievements | C30: Challenges | E30: Way Forward | H30: Actions Planned for Next Period

Sheet Sheet11
B1: PERFORMANCE INDICATORS | C1: Unit of Measure | D1: Achievement
D2: Current Quarter | E2: To-date
A3: 1 | B3: SOLAR HYBRID MINI GRIDS FOR ECONOMIC DEVELOPMENT
A4: 1.1 | B4: Minimum Subsidy Tender for Mini Grids
A5: 1.1.1 | B5: Isolated Mini Grid
A6: 1.1.1.1 | B6: Benefiting Communities | C6: No. | D6: =SUM(MiniGrid!B4) -> 34 | E6: =SUM(MiniGrid!C4) -> 0
A7: 1.1.1.2 | B7: Isolated Mini Grid Approved | C7: No. | D7: =SUM(MiniGrid!B5) -> 0 | E7: =SUM(MiniGrid!C5) -> 0
A8: 1.1.1.3 | B8: Isolated Mini Grid Commissioned | C8: No. | D8: =SUM(MiniGrid!B6) -> 0 | E8: =SUM(MiniGrid!C6) -> 0
A9: 1.1.1.4 | B9: Isolated Mini-Grid Ongoing | C9: No. | D9: =SUM(MiniGrid!B7) -> 0 | E9: =SUM(MiniGrid!C7) -> 0
A10: 1.1.1.5 | B10: Population of Beneficiaries | C10: No. | D10: =SUM(MiniGrid!B8) -> 0 | E10: =SUM(MiniGrid!C8) -> 0
A11: 1.1.1.6 | B11: Population of Female Beneficiaries | C11: No. | D11: =SUM(MiniGrid!B9) -> 0 | E11: =SUM(MiniGrid!C9) -> 0
A12: 1.1.1.7 | B12: Population of Household Beneficiary | C12: No. | D12: =SUM(MiniGrid!B10) -> 0 | E12: =SUM(MiniGrid!C10) -> 0
A13: 1.1.1.8 | B13: Population of Female Headed Household Beneficiaries | C13: No. | D13: =SUM(MiniGrid!B11) -> 0 | E13: =SUM(MiniGrid!C11) -> 0
A14: 1.1.1.9 | B14: Population of MSME Beneficiaries | C14: No. | D14: =SUM(MiniGrid!B12) -> 0 | E14: =SUM(MiniGrid!C12) -> 0
A15: 1.1.1.10 | B15: Population of Female Managed MSME Beneficiaries | C15: No. | D15: =SUM(MiniGrid!B13) -> 0 | E15: =SUM(MiniGrid!C13) -> 0
A16: 1.1.1.11 | B16: Population of New MSMEs enabled | C16: No. | D16: =SUM(MiniGrid!B14) -> 0 | E16: =SUM(MiniGrid!C14) -> 0
A17: 1.1.1.12 | B17: Population of Public Institutition Beneficiaries | C17: No. | D17: =SUM(MiniGrid!B15) -> 0 | E17: =SUM(MiniGrid!C15) -> 0
... A21: 1.1.1.16 | B21: Average outage events per month | C21: No. | D21: =SUM(MiniGrid!B19) -> 0 | E21: =SUM(MiniGrid!C19) -> 0
A22: 1.1.1.19 | B22: Private Sector Fund Mobilised | C22: Naira | D22: =SUM(MiniGrid!B21) -> 0 | E22: =SUM(MiniGrid!C23) -> 0
A23: 1.1.1.21 | B23: Gasoline generator sets replaced | C23: No. | D23: =SUM(MiniGrid!B22) -> 344 | E23: =SUM(MiniGrid!C24) -> 0
A25: 1.1.2 | B25: Interconnected Mini Grid
A26: 1.1.2.1 | B26: Benefiting Communities | C26: No. | D26: =SUM(MiniGrid!B25) -> 35 | E26: =SUM(MiniGrid!C25) -> 0
A27: 1.1.2.2 | B27: Interconnected Mini Grid Approved | C27: No. | D27: =SUM(MiniGrid!B26) -> 0 | E27: =SUM(MiniGrid!C26) -> 0
A28: 1.1.2.3 | B28: Isolated Mini Grid Commissioned | C28: No. | D28: =SUM(MiniGrid!B27) -> 0 | E28: =SUM(MiniGrid!C27) -> 0
A29: 1.1.2.4 | B29: Interconnected Mini-Grid Ongoing | C29: No. | D29: =SUM(MiniGrid!B28) -> 0 | E29: =SUM(MiniGrid!C28) -> 0
A30: 1.1.2.5 | B30: Population of Households connected | C30: No. | D30: =SUM(MiniGrid!B29) -> 0 | E30: =SUM(MiniGrid!C29) -> 0
A31: 1.1.2.6 | B31: Population of Female Households connected | C31: No. | D31: =SUM(MiniGrid!B30) -> 0 | E31: =SUM(MiniGrid!C30) -> 0
A32: 1.1.2.7 | B32: Population of PUE and Economic Users connected | C32: No. | D32: =SUM(MiniGrid!B31) -> 0 | E32: =SUM(MiniGrid!C31) -> 0
A33: 1.1.1.8 | B33: Population of Female Headed Household beneficiaries | C33: No. | D33: =SUM(MiniGrid!B32) -> 0 | E33: =SUM(MiniGrid!C32) -> 0
A34: 1.1.1.9 | B34: Population of MSME beneficiaries | C34: No. | D34: =SUM(MiniGrid!B33) -> 0 | E34: =SUM(MiniGrid!C33) -> 0
A35: 1.1.1.10 | B35: Population of Female Managed MSME beneficiaries | C35: No. | D35: =SUM(MiniGrid!B34) -> 0 | E35: =SUM(MiniGrid!C34) -> 0
A36: 1.1.1.11 | B36: Population of New MSMEs enabled | C36: No. | D36: =SUM(MiniGrid!B35) -> 0 | E36: =SUM(MiniGrid!C35) -> 0
A37: 1.1.1.12 | B37: Population of Public Institutition beneficiary | C37: KW | D37: =SUM(MiniGrid!B36) -> 0 | E37: =SUM(MiniGrid!C36) -> 0
... A41: 1.1.1.16 | B41: Average outage events per month | C41: No. | D41: =SUM(MiniGrid!B40) -> 0 | E41: =SUM(MiniGrid!C40) -> 0
A42: 1.1.1.18 | B42: Private Sector Fund Mobilised | C42: Naira | D42: =SUM(MiniGrid!B42) -> 0 | E42: =SUM(MiniGrid!C42) -> 0
A43: 1.1.1.19 | B43: Gasoline generator sets replaced | C43: No. | D43: =SUM(MiniGrid!B43) -> 36 | E43: =SUM(MiniGrid!C43) -> 0
A45: 1.1.3 | B45: Solar Rooftop Solutions
A46: 1.1.3.1 | B46: Solar Rooftop Solutions Approved | C46: No. | D46: =SUM(MiniGrid!B46) -> 37 | E46: =SUM(MiniGrid!C46) -> 0
A47: 1.1.3.2 | B47: Solar Rooftop Solutions Commissioned | C47: No. | D47: =SUM(MiniGrid!B47) -> 0 | E47: =SUM(MiniGrid!C47) -> 0
A48: 1.1.3.3 | B48: Population of Benefiting Health Institutions | C48: No. | D48: =SUM(MiniGrid!B48) -> 0 | E48: =SUM(MiniGrid!C48) -> 0
...

Sheet FM
B1: DARES PROJECT: FINANCIAL MANAGEMENT PERFORMANCE TEMPLATE
B3: Reporting Period______________________________________
B4: Indicators | E4: Current Quarter | F4: To-date
B5: Quarterly IFRs Submitted
B6: % Budget Execution (Actual vs. Planned)
B7: External Audit produced
B8: Amount Replenished
B9: Amount Converted
B10: Government Contribution
B12: FINANCIAL STATUS
A13: S/N | B13: Component | D13: IDA Allocation | E13: IDA Alllocation | F13: Previous Cumulative Disbursement | G13: Current Quarter Disbursement | H13: Disbursement To-date
A14: 1 | B14: Mini Grids
A15: 1.1 | B15: Minimum Subsidy Tender | C15: Isolated Mini Grids | E15: 95000000
C16: Interconnected Mini Grids | E16: 100000000
C17: Solar Roof Top | E17: 20000000
A18: 1.2 | B18: Performance Based Grants | C18: Isolated Mini Grids | E18: 168000000
C19: Interconnected Mini Grids | E19: 27000000
A20: Total Component 1 | E20: 410000000
A21: 2 | B21: Standalone Solar
A22: 2.1 | B22: Performance Based Grants | C22: SAS Basic Electrification | E22: 230000000
C23: SAS PUE | E23: 50000000
A24: 2.2 | B24: Catalytic Grants | E24: 20000000
A25: Total Component 2 | E25: 300000000
A26: 3 | B26: Technical Assistance
A27: 3.1 | B27: Institutional strengthening | E27: 10000000
A28: 3.2 | B28: Ecosystem building | E28: 20000000
A29: 3.3 | B29: Engagement with States | E29: 10000000
A30: Total Component 3 | E30: 40000000
B31: TOTAL DARES | E31: 750000000
B34: Summary and Next Steps
B35: Key Achievements | D35: Challenges | F35: Way Forward | H35: Actions Planned for Next Period

Sheet Procurement
B2: PROCUREMENT
B3: Reporting Period______________________________________
B4: Category | D4: Measure | E4: Goods | G4: Works | I4: Non-Consulting | K4: Consultancy
E5: Current Quarter | F5: To date | G5: Current Quarter | H5: To date | I5: Current Quarter | J5: To date | K5: Current Quarter | L5: To date
B6: EOI | D6: No
B7: RFP | D7: No
B8: Awarded | D8: No
B9: Contract sum | D9: Naira
B10: Contract Completed | D10: No
B11: Contract On-going | D11: No
B12: *Contract Delayed | D12: No
B15: Summary and Next Steps
B16: Key Achievements | D16: Challenges | G16: Way Forward | J16: Actions Planned for Next Period

Sheet Intergovernmental
B2: INTERGOVERNMENTAL SERVICES
B3: Reporting Period______________________________________
B5: 1. Stakeholder Engagement
B6: Type | C6: Stakeholder Identity | D6: Level (Federal/State) | E6: Purpose of Engagement
B12: 2. MOUs and Agreements
B13: MOU Type | C13: Key Commitments | E13: Status (Signed/ Pending/Under Review)
B20: 3. Issues Identified
B21: Issue Description | C21: Stakeholders Involved | E21: Impact on Project | H21: Action Taken/Recommendation
B26: 4. Planned Activities for Next Reporting Period
B27: Activity | C27: Objective | F27: Target State(s) | H27: Expected Outcome
B65: Key Achievements | C65: Challenges | D65: Way Forward | E65: Actions Planned for Next Period

Sheet Environment
B2: ENVIRONMENTAL SAFEGUARDS
B4: Period: ________________________________
B5: Indicators | C5: Current Quarter | D5: To-date
B6: Occupational Health Safety cases reported | C6: 1 | D6: 2
B7: Sites with undisposed electronic waste, heaps of debris or piles after construction
B8: Sites with Erosion/Flooding issues
B9: Site with Ground/Surface Water pollution
B10: Site with abandoned borrow pits | C10: 3 | D10: 4
B12: Summary and Next Steps
B13: Key Achievements | C13: Challenges | E13: Way Forward | H13: Actions Planned for Next Period

Sheet HR
B2: HUMAN RESOURCES & ADMINISTRATION
B4: Reporting Period______________________________________
B5: Indicators | C5: Current Quarter | D5: To-date
B6: No. of Staff
B7: % of Female Staff
B8: Staff trained
B9: Meetings held and reported
B11: Summary and Next Steps
B12: Key Achievements | C12: Challenges | E12: Way Forward | H12: Actions Planned for Next Period

Sheet Social
B2: SOCIAL SAFEGUARDS PERFORMANCE REPORT
B3: Reporting Period: ________________________________
B4: Indicators | C4: Current Quarter | D4: To-date
B5: Volountary Land Donation Protocol cases reported
B6: % of Volountary Land Donation Protocol cases resolved
B7: Exclusion and discrimination cases reported
B8: % of Exclusion and discrimination cases resolved
B9: GBV/SH/SEA cases reported
B10: Labour Management cases reported
B11: % of Labour Management cases resolved
B14: Summary and Next Steps
B15: Key Achievements | C15: Challenges | E15: Way Forward | H15: Actions Planned for Next Period

Sheet Communication
B2: COMMUNICATION
B4: Reporting Period
B5: Indicators | C5: Current Quarter | D5: To-date
B6: Public awareness campaigns conducted
B7: Media engagement conducted
B8: Stakeholder engagement events held
B9: Website/portal update frequency
B10: Social media posted
B11: Online inquiries received
B12: Online inquiries addressed
B13: Internal knowledge sharing sessions held
B14: Publications produced and distributed
B15: Jingles and media programmes aired
B17: Summary and Next Steps
B18: Key Achievements | C18: Challenges | E18: Way Forward | H18: Actions Planned for Next Period

Sheet IT
B2: INFORMATION AND TECHNOLOGY
B4: Reporting Period: ____________________________________________
B6: Indicators | C6: Current Quarter | D6: To-date
B7: Remote Monitoring, Data Centre, and Project Feedback System
B8: Number of data sources connected to the DARES data center
B9: Sites minigrid sites connected to the DARES Data center
B10: Total Solar Homes System connected to data center
B11: Total number of external stakeholder visiting the Data center
B13: Smart Office Solutions, Website, and Gmail
B14: Staff onboarded onto Smart Office platforms
B15: Total no of reports submittted
B16: Total no of reports approved
B17: Total number of visits to the office
B18: Total meeting schedules
B19: Total meeting attended
... B38: Summary and Next Steps
B39: Key Achievements | C39: Challenges | E39: Way Forward | H39: Actions Planned for Next Period
